Workbook

Sheet 净收益测算
A1: 净收益测算
A2: 估价对象: [请输入地址] | C2: 价值时点: [请输入日期]
A3: 图例: 蓝色字=可修改输入 | 黑色字=公式自动计算 | 黄色底=关键参数
A5: 项目 | B5: 数值 | C5: 数据来源
A6: 潜在毛租金收入 (元/m²·年) | B6: 600 | C6: 4.3.7条: 租赁收入法; 来源: 市场调查/合同
A7: 空置和收租损失率 | B7: 0.05 | C7: 4.3.8条; 区域空置率调查
A8: 有效毛收入 (元/m²·年) | B8: =ROUND(B6*(1-B7),0) | C8: 公式
A9: 其他收入 (元/m²·年) | B9: 50 | C9: 押金利息/停车费/广告位等
A10: 房地产税 | C10: 城市房地产税/城镇土地使用税
A11: 房屋保险费 | C11: 建筑物及设备保险费
A12: 物业服务费 | C12: 物业管理公司收费
A13: 管理费用 | C13: 管理人员工资/办公费等
A14: 维修费 | C14: 日常维修和大修基金
A15: 水电费 | C15: 公共区域水电
A16: 其他运营费用 | C16: 其他正常运营必要支出
A17: 运营费用合计 | B17: =ROUND(SUM(B10:B16),0) | C17: 公式
A18: 净收益 NOI (元/m²·年) | B18: =ROUND(B8+B9-B17,0) | C18: 4.3.9条: 净收益 = 有效毛收入 - 运营费用
A19: 最近三年实际净收益: Y-2 | C19: 4.3.11条: 必须调查近三年实际数据
A20: 最近三年实际净收益: Y-1 | C20: 与预测值差异需分析修正
A21: 最近三年实际净收益: Y-0 | C21: 以正常客观值为准

Sheet 收益价值
A1: 收益价值计算
A2: 报酬率 Y | D2: 方法: [市场提取/累加/排序]
A3: 收益期 (年) | D3: 模式: [全剩余寿命/持有加转售]
A5: 期数 | B5: 净收益 (元/m²) | C5: 折现系数 | D5: 现值 (元/m²) | E5: 备注
A6: 1 | B6: =ROUND(IF(A6<=$C$3, 净收益测算!B18, 0),0) | C6: =IF(A6<=$C$3,1/(1+$C$2)^A6,0) | D6: =ROUND(B6*C6,0)
A7: 2 | B7: =ROUND(IF(A7<=$C$3, 净收益测算!B18, 0),0) | C7: =IF(A7<=$C$3,1/(1+$C$2)^A7,0) | D7: =ROUND(B7*C7,0)
A8: 3 | B8: =ROUND(IF(A8<=$C$3, 净收益测算!B18, 0),0) | C8: =IF(A8<=$C$3,1/(1+$C$2)^A8,0) | D8: =ROUND(B8*C8,0)
A9: 4 | B9: =ROUND(IF(A9<=$C$3, 净收益测算!B18, 0),0) | C9: =IF(A9<=$C$3,1/(1+$C$2)^A9,0) | D9: =ROUND(B9*C9,0)
A10: 5 | B10: =ROUND(IF(A10<=$C$3, 净收益测算!B18, 0),0) | C10: =IF(A10<=$C$3,1/(1+$C$2)^A10,0) | D10: =ROUND(B10*C10,0)
A11: 6 | B11: =ROUND(IF(A11<=$C$3, 净收益测算!B18, 0),0) | C11: =IF(A11<=$C$3,1/(1+$C$2)^A11,0) | D11: =ROUND(B11*C11,0)
A12: 7 | B12: =ROUND(IF(A12<=$C$3, 净收益测算!B18, 0),0) | C12: =IF(A12<=$C$3,1/(1+$C$2)^A12,0) | D12: =ROUND(B12*C12,0)
A13: 8 | B13: =ROUND(IF(A13<=$C$3, 净收益测算!B18, 0),0) | C13: =IF(A13<=$C$3,1/(1+$C$2)^A13,0) | D13: =ROUND(B13*C13,0)
A14: 9 | B14: =ROUND(IF(A14<=$C$3, 净收益测算!B18, 0),0) | C14: =IF(A14<=$C$3,1/(1+$C$2)^A14,0) | D14: =ROUND(B14*C14,0)
A15: 10 | B15: =ROUND(IF(A15<=$C$3, 净收益测算!B18, 0),0) | C15: =IF(A15<=$C$3,1/(1+$C$2)^A15,0) | D15: =ROUND(B15*C15,0)
A16: 11 | B16: =ROUND(IF(A16<=$C$3, 净收益测算!B18, 0),0) | C16: =IF(A16<=$C$3,1/(1+$C$2)^A16,0) | D16: =ROUND(B16*C16,0)
A17: 12 | B17: =ROUND(IF(A17<=$C$3, 净收益测算!B18, 0),0) | C17: =IF(A17<=$C$3,1/(1+$C$2)^A17,0) | D17: =ROUND(B17*C17,0)
A18: 13 | B18: =ROUND(IF(A18<=$C$3, 净收益测算!B18, 0),0) | C18: =IF(A18<=$C$3,1/(1+$C$2)^A18,0) | D18: =ROUND(B18*C18,0)
A19: 14 | B19: =ROUND(IF(A19<=$C$3, 净收益测算!B18, 0),0) | C19: =IF(A19<=$C$3,1/(1+$C$2)^A19,0) | D19: =ROUND(B19*C19,0)
A20: 15 | B20: =ROUND(IF(A20<=$C$3, 净收益测算!B18, 0),0) | C20: =IF(A20<=$C$3,1/(1+$C$2)^A20,0) | D20: =ROUND(B20*C20,0)
A21: 16 | B21: =ROUND(IF(A21<=$C$3, 净收益测算!B18, 0),0) | C21: =IF(A21<=$C$3,1/(1+$C$2)^A21,0) | D21: =ROUND(B21*C21,0)
A22: 17 | B22: =ROUND(IF(A22<=$C$3, 净收益测算!B18, 0),0) | C22: =IF(A22<=$C$3,1/(1+$C$2)^A22,0) | D22: =ROUND(B22*C22,0)
A23: 18 | B23: =ROUND(IF(A23<=$C$3, 净收益测算!B18, 0),0) | C23: =IF(A23<=$C$3,1/(1+$C$2)^A23,0) | D23: =ROUND(B23*C23,0)
A24: 19 | B24: =ROUND(IF(A24<=$C$3, 净收益测算!B18, 0),0) | C24: =IF(A24<=$C$3,1/(1+$C$2)^A24,0) | D24: =ROUND(B24*C24,0)
A25: 20 | B25: =ROUND(IF(A25<=$C$3, 净收益测算!B18, 0),0) | C25: =IF(A25<=$C$3,1/(1+$C$2)^A25,0) | D25: =ROUND(B25*C25,0)
A26: 21 | B26: =ROUND(IF(A26<=$C$3, 净收益测算!B18, 0),0) | C26: =IF(A26<=$C$3,1/(1+$C$2)^A26,0) | D26: =ROUND(B26*C26,0)
A27: 22 | B27: =ROUND(IF(A27<=$C$3, 净收益测算!B18, 0),0) | C27: =IF(A27<=$C$3,1/(1+$C$2)^A27,0) | D27: =ROUND(B27*C27,0)
A28: 23 | B28: =ROUND(IF(A28<=$C$3, 净收益测算!B18, 0),0) | C28: =IF(A28<=$C$3,1/(1+$C$2)^A28,0) | D28: =ROUND(B28*C28,0)
A29: 24 | B29: =ROUND(IF(A29<=$C$3, 净收益测算!B18, 0),0) | C29: =IF(A29<=$C$3,1/(1+$C$2)^A29,0) | D29: =ROUND(B29*C29,0)
A30: 25 | B30: =ROUND(IF(A30<=$C$3, 净收益测算!B18, 0),0) | C30: =IF(A30<=$C$3,1/(1+$C$2)^A30,0) | D30: =ROUND(B30*C30,0)
A31: 26 | B31: =ROUND(IF(A31<=$C$3, 净收益测算!B18, 0),0) | C31: =IF(A31<=$C$3,1/(1+$C$2)^A31,0) | D31: =ROUND(B31*C31,0)
A32: 27 | B32: =ROUND(IF(A32<=$C$3, 净收益测算!B18, 0),0) | C32: =IF(A32<=$C$3,1/(1+$C$2)^A32,0) | D32: =ROUND(B32*C32,0)
A33: 28 | B33: =ROUND(IF(A33<=$C$3, 净收益测算!B18, 0),0) | C33: =IF(A33<=$C$3,1/(1+$C$2)^A33,0) | D33: =ROUND(B33*C33,0)
A34: 29 | B34: =ROUND(IF(A34<=$C$3, 净收益测算!B18, 0),0) | C34: =IF(A34<=$C$3,1/(1+$C$2)^A34,0) | D34: =ROUND(B34*C34,0)
A35: 30 | B35: =ROUND(IF(A35<=$C$3, 净收益测算!B18, 0),0) | C35: =IF(A35<=$C$3,1/(1+$C$2)^A35,0) | D35: =ROUND(B35*C35,0)
A36: 31 | B36: =ROUND(IF(A36<=$C$3, 净收益测算!B18, 0),0) | C36: =IF(A36<=$C$3,1/(1+$C$2)^A36,0) | D36: =ROUND(B36*C36,0)
A37: 32 | B37: =ROUND(IF(A37<=$C$3, 净收益测算!B18, 0),0) | C37: =IF(A37<=$C$3,1/(1+$C$2)^A37,0) | D37: =ROUND(B37*C37,0)
A38: 33 | B38: =ROUND(IF(A38<=$C$3, 净收益测算!B18, 0),0) | C38: =IF(A38<=$C$3,1/(1+$C$2)^A38,0) | D38: =ROUND(B38*C38,0)
A39: 34 | B39: =ROUND(IF(A39<=$C$3, 净收益测算!B18, 0),0) | C39: =IF(A39<=$C$3,1/(1+$C$2)^A39,0) | D39: =ROUND(B39*C39,0)
A40: 35 | B40: =ROUND(IF(A40<=$C$3, 净收益测算!B18, 0),0) | C40: =IF(A40<=$C$3,1/(1+$C$2)^A40,0) | D40: =ROUND(B40*C40,0)
A41: 36 | B41: =ROUND(IF(A41<=$C$3, 净收益测算!B18, 0),0) | C41: =IF(A41<=$C$3,1/(1+$C$2)^A41,0) | D41: =ROUND(B41*C41,0)
...
