Workbook
Name 空置明细表: #REF!
Name 空置明细表: #REF!

Sheet 使用说明
A1: 房地产评估明细表 — 计算模板使用说明
A2: 本模板从真实评估案例模糊化生成，保留全部公式和结构。使用时替换占位数据即可。
A4: 一、Sheet 目录与用途
A5: Sheet 名称 | B5: 用途 | C5: 关键内容 | D5: 必填字段 / 注意事项
A6: 评估明细表 | B6: 估价对象基本信息 + 结果汇总 | C6: 委托人、权属人、面积、评估单价/总价、原购买价 | D6: N6/N7 评估单价（手动输入）；其余多为公式引用
A7: 住宅-实物状况 | B7: 估价对象实物状况描述 | C7: 建成年代、楼层、朝向、装修、配套设施（学校/医院/超市等） | D7: 区位状况、实物状况文字描述（可比案例调整依据）
A8: 单价修正明细表-住宅 | B8: 可比实例单价修正计算 | C8: 成交单价→交易情况修正→市场状况调整→区位/实物/权益调整→比准单价 | D8: 修正系数（手动输入）；比准单价=公式自动计算
A9: 住宅-收益法测算 | B9: 收益法测算过程 | C9: 租金收入→空置率→运营费用→净收益→报酬率→收益价值 | D9: 月租金、报酬率、剩余年限（手动输入）；收益价值=公式
A10: 租金比较法 | B10: 租金市场比较法测算 | C10: 可比租金实例→修正→比准租金→有效毛收入 | D10: 可比租金实例数据（手动输入）；比准租金=公式
A11: 租金单价 | B11: 租金案例数据库 | C11: 各小区租金挂牌价、面积、楼层、来源链接 | D11: 租金数据采集（手动输入）；来源链接可留空
A12: 住宅-收益率 | B12: 报酬率确定过程 | C12: 安全利率+风险调整值法 / 市场提取法 | D12: 安全利率、风险调整值（手动输入）；报酬率=公式
A13: 市场价比较法 | B13: 市场价比较法综合测算 | C13: 可比实例汇总→修正→比准单价→权重→最终单价 | D13: E4/F4/G4 成交单价、E24/F24/G24 面积（手动输入）；比准单价=公式
A14: 二手房案例 | B14: 二手房成交案例数据库 | C14: 小区名称、面积、总价、单价、成交日期 | D14: 二手房成交数据（手动输入）
A15: 可比案例 | B15: 可比实例详细数据 | C15: 名称、位置、面积、成交价、单价、成交日期、修正系数 | D15: G列 成交总价（手动输入）；修正系数=公式
A16: 租金案例 | B16: 租金案例数据库 | C16: 小区名称、面积、月租金、单价、楼层、来源 | D16: 租金案例数据（手动输入）
A18: 二、公式逻辑说明
A19: 计算环节 | B19: 公式逻辑 | C19: 涉及 Sheet | D19: 说明
A20: 评估单价 | B20: 评估明细表 N6 = 市场价比较法!最终比准单价 | C20: 评估明细表 → 市场价比较法 | D20: 比较法结果直接引用到汇总表
A21: 比准单价 | B21: 比准单价 = 成交单价 × 交易情况修正 × 市场状况调整 × 区位调整 × 实物调整 × 权益调整 | C21: 单价修正明细表-住宅 / 市场价比较法 | D21: 各修正系数乘积，乘法链
A22: 收益价值 | B22: V = A/Y × [1 - 1/(1+Y)^n] | C22: 住宅-收益法测算 | D22: A=年净收益, Y=报酬率, n=剩余年限
A23: 净收益 | B23: 净收益 = 有效毛收入 - 运营费用 = 月租金×12×(1-空置率) - 运营费用 | C23: 住宅-收益法测算 | D23: 空置率通常取 5%-10%
A24: 报酬率 | B24: 报酬率 = 安全利率 + 风险调整值 | C24: 住宅-收益率 | D24: 累加法确定
A25: 有效毛收入 | B25: 有效毛收入 = 月租金 × 12 × (1 - 空置率) | C25: 租金比较法 → 住宅-收益法测算 | D25: 租金比较法计算比准租金后引用
A26: 最终结果 | B26: 评估明细表总价 = 评估单价 × 面积 | C26: 评估明细表 | D26: 面积来自估价对象基本信息
A28: 三、使用流程
A29: 1. 复制本模板，重命名为具体项目
A30: 2. 在「评估明细表」填写估价对象基本信息（委托人、地址、面积等）
A31: 3. 在「住宅-实物状况」描述估价对象实物状况（供可比案例调整参考）
A32: 4. 在「市场价比较法」输入可比实例成交数据（E4/F4/G4 单价、E24/F24/G24 面积）
A33: 5. 在「单价修正明细表-住宅」调整修正系数（交易情况/市场状况/区位/实物/权益）
A34: 6. 在「租金单价」和「租金案例」采集租金数据
A35: 7. 在「租金比较法」计算比准租金 → 引用到「住宅-收益法测算」
A36: 8. 在「住宅-收益率」确定报酬率（累加法或市场提取法）
A37: 9. 在「住宅-收益法测算」检查收益价值计算结果
A38: 10. 「评估明细表」N6 单价已通过公式自动引用，检查最终结果
A40: 四、注意事项
... A46: ⚠️ 本模板数据已模糊化处理，所有姓名/地址/价格均为占位符，请替换为实际数据

Sheet 评估明细表
B1: 资产评估结果明细表
B2: 评估基准日： | J2: 42879
B3: 委托人：XX投资有限公司 | P3: 金额单位：人民币元
B4: 序号 | C4: 权属证号 | D4: 坐落 | E4: 权属人 | F4: 用途 | G4: 装修 | H4: 土地到期日 | I4: 房屋结构及总层数 | J4: 所在楼层 | K4: 竣工时间 | L4: 套内建筑面积（㎡） | M4: 建筑面积（㎡） | N4: 评估价值 | P4: 备注 | W4: 原购买价（含9%税） | Y4: 增减值 | Z4: 增减率（%） | AA4: 单价增值
N5: 评估单价 （元/㎡） | O5: 评估总价 （元） | Q5: 购买时间 | R5: 协议单价 | U5: 实用率 | W5: 购买单价 | X5: 总价
B6: 1 | C6: 《商品房买卖合同》 | D6: XX市XX区XX路XX号XX小区XX栋XX房 | E6: XX投资有限公司 | F6: 成套住宅 | G6: 精致 | H6: 61568 | I6: 钢混5层 | J6: 第1-5层 | K6: 40725 | L6: 540 | M6: 580 | N6: 38000 | O6: ==ROUND(M6*N6,0) | S6: ==+R6/N6-1 | T6: ==R6*M6 | U6: ==+L6/M6 | W6: 38000 | X6: ==W6*M8 | Y6: ==O6-X6 | Z6: ==+Y6/X6*100 | AA6: ==W6-N6
F7: 车库 | J7: 第1层 | L7: 38 | M7: 40 | N7: 38000 | O7: ==ROUND(+M7*N7,0)
B8: 合 计 | M8: ==M6+M7 | O8: ==ROUND(O6+O7,0)
B9: 评估机构：XX土地房地产与资产评估有限公司 | J9: 评估人员：评估师A、评估师B
B10: 日期：2028年08月11日 | R10: ==R6-N6

Sheet 住宅-实物状况
A3: 序号 | C3: 项目名称 | D3: 房号 | E3: 坐落 | F3: 用途 | G3: 建筑面积（㎡） | H3: 建筑物结构 | I3: 建成年月 | J3: 外墙面 | K3: 总楼层/所在楼层 | L3: 朝向 | M3: 设施设备 | N3: 平面布局 | O3: 户型 | P3: 室内装修 | Q3: 备注 | R3: 请提供平面图
A4: 1 | C4: ==+#REF! | D4: ==+评估明细表!F4 | E4: ==+#REF! | F4: 住宅 | G4: ==+#REF! | H4: 钢混 | I4: 约2021年6月 | J4: 涂料 | L4: 南 | M4: 二部电梯、水、电、消防、厨卫设施齐备 | N4: 一层四户 | O4: 3房2厅1厨2卫1阳台 | P4: 普通
A5: 2 | C5: ==+评估明细表!E4 | D5: ==+评估明细表!F5 | E5: ==+#REF! | F5: 住宅 | G5: ==+#REF! | H5: 钢混 | I5: 约2021年6月 | J5: 涂料 | L5: 东南 | M5: 二部电梯、水、电、消防、厨卫设施齐备 | N5: 一层四户 | O5: 3房2厅1厨2卫1阳台 | P5: 普通
A6: 3 | C6: ==+评估明细表!E6 | D6: ==+评估明细表!F6 | E6: ==+#REF! | F6: 住宅 | G6: ==+#REF! | H6: 钢混 | I6: 约2021年6月 | J6: 涂料 | L6: 南 | M6: 二部电梯、水、电、消防、厨卫设施齐备 | N6: 一层四户 | O6: 3房2厅1厨2卫1阳台 | P6: 普通
A7: 4 | C7: ==+#REF! | D7: ==+#REF! | E7: ==+#REF! | F7: 住宅 | G7: ==+#REF! | H7: 钢混 | I7: 约2021年6月 | J7: 涂料 | L7: 南 | M7: 二部电梯、水、电、消防、厨卫设施齐备 | N7: 一层四户 | O7: 3房2厅1厨2卫1阳台 | P7: 普通
A8: 5 | C8: ==+#REF! | D8: ==+#REF! | E8: ==+#REF! | F8: 住宅 | G8: ==+#REF! | H8: 钢混 | I8: 约2021年6月 | J8: 涂料 | L8: 南 | M8: 二部电梯、水、电、消防、厨卫设施齐备 | N8: 一层四户 | O8: 3房2厅1厨2卫1阳台 | P8: 普通
A9: 6 | C9: ==+#REF! | D9: ==+#REF! | E9: ==+#REF! | F9: 住宅 | G9: ==+#REF! | H9: 钢混 | I9: 约2021年6月 | J9: 涂料 | L9: 南 | M9: 二部电梯、水、电、消防、厨卫设施齐备 | N9: 一层四户 | O9: 3房2厅1厨2卫1阳台 | P9: 普通
A10: 7 | C10: ==+#REF! | D10: ==+#REF! | E10: ==+#REF! | F10: 住宅 | G10: ==+#REF! | H10: 钢混 | I10: 约2021年6月 | J10: 涂料 | L10: 南 | M10: 二部电梯、水、电、消防、厨卫设施齐备 | N10: 一层四户 | O10: 3房2厅1厨2卫1阳台 | P10: 普通
A11: 8 | C11: ==+#REF! | D11: ==+#REF! | E11: ==+#REF! | F11: 住宅 | G11: ==+#REF! | H11: 钢混 | I11: 约2021年6月 | J11: 涂料 | L11: 东南 | M11: 二部电梯、水、电、消防、厨卫设施齐备 | N11: 一层四户 | O11: 3房2厅1厨2卫1阳台 | P11: 普通
A12: 9 | C12: ==+#REF! | D12: ==+#REF! | E12: ==+#REF! | F12: 住宅 | G12: ==+#REF! | H12: 钢混 | I12: 约2021年6月 | J12: 涂料 | L12: 南 | M12: 二部电梯、水、电、消防、厨卫设施齐备 | N12: 一层四户 | O12: 3房2厅1厨2卫1阳台 | P12: 普通
A13: 10 | C13: ==+#REF! | D13: ==+#REF! | E13: ==+#REF! | F13: 住宅 | G13: ==+#REF! | H13: 钢混 | I13: 约2021年6月 | J13: 涂料 | L13: 东南 | M13: 二部电梯、水、电、消防、厨卫设施齐备 | N13: 一层四户 | O13: 3房2厅1厨2卫1阳台 | P13: 普通
A14: 11 | C14: ==+#REF! | D14: ==+#REF! | E14: ==+#REF! | F14: 住宅 | G14: ==+#REF! | H14: 钢混 | I14: 约2021年6月 | J14: 涂料 | L14: 东南 | M14: 二部电梯、水、电、消防、厨卫设施齐备 | N14: 一层四户 | O14: 3房2厅1厨2卫1阳台 | P14: 普通
A15: 12 | C15: ==+#REF! | D15: ==+#REF! | E15: ==+#REF! | F15: 住宅 | G15: ==+#REF! | H15: 钢混 | I15: 约2021年6月 | J15: 涂料 | L15: 南 | M15: 二部电梯、水、电、消防、厨卫设施齐备 | N15: 一层四户 | O15: 3房2厅1厨2卫1阳台 | P15: 普通
A16: 13 | C16: ==+#REF! | D16: ==+#REF! | E16: ==+#REF! | F16: 住宅 | G16: ==+#REF! | H16: 钢混 | I16: 约2021年6月 | J16: 涂料 | L16: 东南 | M16: 二部电梯、水、电、消防、厨卫设施齐备 | N16: 一层四户 | O16: 3房2厅1厨2卫1阳台 | P16: 普通
A17: 14 | C17: ==+#REF! | D17: ==+#REF! | E17: ==+#REF! | F17: 住宅 | G17: ==+#REF! | H17: 钢混 | I17: 约2021年6月 | J17: 涂料 | L17: 南 | M17: 二部电梯、水、电、消防、厨卫设施齐备 | N17: 一层四户 | O17: 3房2厅1厨2卫1阳台 | P17: 普通
A18: 15 | C18: ==+#REF! | D18: ==+#REF! | E18: ==+#REF! | F18: 住宅 | G18: ==+#REF! | H18: 钢混 | I18: 约2021年6月 | J18: 涂料 | L18: 东南 | M18: 二部电梯、水、电、消防、厨卫设施齐备 | N18: 一层四户 | O18: 3房2厅1厨2卫1阳台 | P18: 普通
... A24: 21 | C24: ==+#REF! | D24: ==+#REF! | E24: ==+#REF! | F24: 住宅 | G24: ==+#REF! | H24: 钢混 | I24: 约2021年6月 | J24: 涂料 | L24: 东南 | M24: 二部电梯、水、电、消防、厨卫设施齐备 | N24: 一层四户 | O24: 3房2厅1厨2卫1阳台 | P24: 普通
A25: 22 | C25: ==+#REF! | D25: ==+#REF! | E25: ==+#REF! | F25: 住宅 | G25: ==+#REF! | H25: 钢混 | J25: 涂料 | L25: 南向 | M25: 二部电梯、水、电、消防、厨卫设施齐备 | N25: 一层四户 | O25: 3房2厅1厨2卫1阳台 | P25: 普通
A26: 23 | C26: ==+#REF! | D26: ==+#REF! | E26: ==+#REF! | F26: 住宅 | G26: ==+#REF! | H26: 钢混 | J26: 涂料 | L26: 南向 | M26: 二部电梯、水、电、消防、厨卫设施齐备 | N26: 一层四户 | O26: 3房2厅1厨2卫1阳台 | P26: 普通
A27: 24 | C27: ==+#REF! | D27: ==+#REF! | E27: ==+#REF! | F27: 住宅 | G27: ==+#REF! | H27: 钢混 | J27: 涂料 | L27: 南向 | M27: 二部电梯、水、电、消防、厨卫设施齐备 | N27: 一层四户 | O27: 3房2厅1厨2卫1阳台 | P27: 普通
A28: 25 | C28: ==+#REF! | D28: ==+#REF! | E28: ==+#REF! | F28: 住宅 | G28: ==+#REF! | H28: 钢混 | J28: 涂料 | L28: 南向 | M28: 二部电梯、水、电、消防、厨卫设施齐备 | N28: 一层四户 | O28: 3房2厅1厨2卫1阳台 | P28: 普通
A29: 26 | C29: ==+#REF! | D29: ==+#REF! | E29: ==+#REF! | F29: 住宅 | G29: ==+#REF! | H29: 钢混 | J29: 涂料 | L29: 南向 | M29: 二部电梯、水、电、消防、厨卫设施齐备 | N29: 一层四户 | O29: 3房2厅1厨2卫1阳台 | P29: 普通
A30: 27 | C30: ==+#REF! | D30: ==+#REF! | E30: ==+#REF! | F30: 住宅 | G30: ==+#REF! | H30: 钢混 | J30: 涂料 | L30: 南向 | M30: 二部电梯、水、电、消防、厨卫设施齐备 | N30: 一层四户 | O30: 3房2厅1厨2卫1阳台 | P30: 普通
A31: 28 | C31: ==+#REF! | D31: ==+#REF! | E31: ==+#REF! | F31: 住宅 | G31: ==+#REF! | H31: 钢混 | J31: 涂料 | L31: 南向 | M31: 二部电梯、水、电、消防、厨卫设施齐备 | N31: 一层四户 | O31: 3房2厅1厨2卫1阳台 | P31: 普通
A32: 29 | C32: ==+#REF! | D32: ==+#REF! | E32: ==+#REF! | F32: 住宅 | G32: ==+#REF! | H32: 钢混 | J32: 涂料 | L32: 南向 | M32: 二部电梯、水、电、消防、厨卫设施齐备 | N32: 一层四户 | O32: 3房2厅1厨2卫1阳台 | P32: 普通
A33: 30 | C33: ==+#REF! | D33: ==+#REF! | E33: ==+#REF! | F33: 住宅 | G33: ==+#REF! | H33: 钢混 | J33: 涂料 | L33: 南向 | M33: 二部电梯、水、电、消防、厨卫设施齐备 | N33: 一层四户 | O33: 3房2厅1厨2卫1阳台 | P33: 普通
A34: 31 | C34: ==+#REF! | D34: ==+#REF! | E34: ==+#REF! | F34: 住宅 | G34: ==+#REF! | H34: 钢混 | J34: 涂料 | L34: 南向 | M34: 二部电梯、水、电、消防、厨卫设施齐备 | N34: 一层四户 | O34: 3房2厅1厨2卫1阳台 | P34: 普通
A35: 32 | C35: ==+#REF! | D35: ==+#REF! | E35: ==+#REF! | F35: 住宅 | G35: ==+#REF! | H35: 钢混 | J35: 涂料 | L35: 南向 | M35: 二部电梯、水、电、消防、厨卫设施齐备 | N35: 一层四户 | O35: 3房2厅1厨2卫1阳台 | P35: 普通
A36: 33 | C36: ==+#REF! | D36: ==+#REF! | E36: ==+#REF! | F36: 住宅 | G36: ==+#REF! | H36: 钢混 | J36: 涂料 | L36: 南向 | M36: 二部电梯、水、电、消防、厨卫设施齐备 | N36: 一层四户 | O36: 3房2厅1厨2卫1阳台 | P36: 普通
... A74: 71 | C74: ==+#REF! | D74: ==+#REF! | E74: ==+#REF! | F74: 住宅 | G74: ==+#REF! | H74: 钢混 | J74: 涂料 | L74: 南北 | M74: 二部电梯、水、电、消防、厨卫设施齐备 | N74: 一层二户 | O74: 4房2厅1厨2卫2阳台 | P74: 普通
A75: 72 | C75: ==+#REF! | D75: ==+#REF! | E75: ==+#REF! | F75: 住宅 | G75: ==+#REF! | H75: 钢混 | I75: 约2022年6月 | J75: 涂料 | L75: 南北 | M75: 二部电梯、水、电、消防、厨卫设施齐备 | N75: 一层四户 | O75: 3房2厅1厨2卫1阳台 | P75: 普通
A76: 73 | C76: ==+#REF! | D76: ==+#REF! | E76: ==+#REF! | F76: 住宅 | G76: ==+#REF! | H76: 钢混 | J76: 涂料 | L76: 南北 | M76: 二部电梯、水、电、消防、厨卫设施齐备 | N76: 一层四户 | O76: 3房2厅1厨2卫1阳台 | P76: 普通
A77: 74 | C77: ==+#REF! | D77: ==+#REF! | E77: ==+#REF! | F77: 住宅 | G77: ==+#REF! | H77: 钢混 | J77: 涂料 | L77: 南北 | M77: 二部电梯、水、电、消防、厨卫设施齐备 | N77: 一层四户 | O77: 3房2厅1厨2卫1阳台 | P77: 普通
A78: 75 | C78: ==+#REF! | D78: ==+#REF! | E78: ==+#REF! | F78: 住宅 | G78: ==+#REF! | H78: 钢混 | J78: 涂料 | L78: 南北 | M78: 二部电梯、水、电、消防、厨卫设施齐备 | N78: 一层四户 | O78: 3房2厅1厨2卫1阳台 | P78: 普通
A79: 76 | C79: ==+#REF! | D79: ==+#REF! | E79: ==+#REF! | F79: 住宅 | G79: ==+#REF! | H79: 钢混 | J79: 涂料 | L79: 南北 | M79: 二部电梯、水、电、消防、厨卫设施齐备 | N79: 一层四户 | O79: 3房2厅1厨2卫1阳台 | P79: 普通
A80: 77 | C80: ==+#REF! | D80: ==+#REF! | E80: ==+#REF! | F80: 住宅 | G80: ==+#REF! | H80: 钢混 | J80: 涂料 | L80: 南北 | M80: 二部电梯、水、电、消防、厨卫设施齐备 | N80: 一层四户 | O80: 3房2厅1厨2卫1阳台 | P80: 普通
A81: 78 | C81: ==+#REF! | D81: ==+#REF! | E81: ==+#REF! | F81: 住宅 | G81: ==+#REF! | H81: 钢混 | J81: 涂料 | L81: 南北 | M81: 二部电梯、水、电、消防、厨卫设施齐备 | N81: 一层四户 | O81: 3房2厅1厨2卫1阳台 | P81: 普通
A82: 79 | C82: ==+#REF! | D82: ==+#REF! | E82: ==+#REF! | F82: 住宅 | G82: ==+#REF! | H82: 钢混 | J82: 涂料 | L82: 南北 | M82: 二部电梯、水、电、消防、厨卫设施齐备 | N82: 一层四户 | O82: 3房2厅1厨2卫1阳台 | P82: 普通
A83: 80 | C83: ==+#REF! | D83: ==+#REF! | E83: ==+#REF! | F83: 住宅 | G83: ==+#REF! | H83: 钢混 | J83: 涂料 | L83: 南北 | M83: 二部电梯、水、电、消防、厨卫设施齐备 | N83: 一层四户 | O83: 3房2厅1厨2卫1阳台 | P83: 普通
A84: 81 | C84: ==+#REF! | D84: ==+#REF! | E84: ==+#REF! | F84: 住宅 | G84: ==+#REF! | H84: 钢混 | J84: 涂料 | L84: 南北 | M84: 二部电梯、水、电、消防、厨卫设施齐备 | N84: 一层四户 | O84: 3房2厅1厨2卫1阳台 | P84: 普通
...

Sheet 单价修正明细表-住宅
G2: 修正明细表
B4: 序号 | C4: 房号 | D4: 建筑面积 | E4: 类型 | F4: 基价（元/㎡） | G4: 楼层修正（%） | H4: 朝向修正（%） | I4: 面积修正（%） | J4: 装修修正（元） | K4: 评估单价(元/㎡) | L4: 备注
B5: 1 | C5: 1栋201 | D5: 88.9 | E5: 住宅 | F5: 26800 | G5: -0.0465 | H5: 0 | I5: 0 | J5: 0 | K5: ==ROUND(+F5*(1+G5+H5+I5)+J5,-2) | N5: 25600 | O5: ==+N5-K5
B6: 2 | C6: 1栋202 | D6: 98.63 | E6: 住宅 | F6: 26800 | G6: -0.0465 | H6: 0 | J6: 0 | K6: ==ROUND(+F6*(1+G6+H6+I6)+J6,-2) | N6: 25600 | O6: ==+N6-K6
B7: 3 | C7: 1栋203 | D7: 98.63 | E7: 住宅 | F7: 26800 | G7: -0.0465 | H7: 0 | J7: 0 | K7: ==ROUND(+F7*(1+G7+H7+I7)+J7,-2) | N7: 25600 | O7: ==+N7-K7
B8: 4 | C8: 1栋204 | D8: 78.98 | E8: 住宅 | F8: 26800 | G8: -0.0465 | H8: 0 | J8: 0 | K8: ==ROUND(+F8*(1+G8+H8+I8)+J8,-2) | N8: 25600 | O8: ==+N8-K8
B9: 5 | C9: 1栋205 | D9: 88.78 | E9: 住宅 | F9: 26800 | G9: -0.0465 | H9: 0 | J9: 0 | K9: ==ROUND(+F9*(1+G9+H9+I9)+J9,-2) | N9: 25600 | O9: ==+N9-K9
B10: 6 | C10: 1栋206 | D10: 88.78 | E10: 住宅 | F10: 26800 | G10: -0.0465 | H10: 0 | J10: 0 | K10: ==ROUND(+F10*(1+G10+H10+I10)+J10,-2) | N10: 25600 | O10: ==+N10-K10
B11: 7 | C11: 1栋301 | D11: 88.9 | E11: 住宅 | F11: 26800 | G11: -0.0434 | H11: 0 | J11: 0 | K11: ==ROUND(+F11*(1+G11+H11+I11)+J11,-2) | N11: 25600 | O11: ==+N11-K11
B12: 8 | C12: 1栋302 | D12: 98.63 | E12: 住宅 | F12: 26800 | G12: -0.0434 | H12: 0 | J12: 0 | K12: ==ROUND(+F12*(1+G12+H12+I12)+J12,-2) | N12: 25600 | O12: ==+N12-K12
B13: 9 | C13: 1栋303 | D13: 98.63 | E13: 住宅 | F13: 26800 | G13: -0.0434 | H13: 0 | J13: 0 | K13: ==ROUND(+F13*(1+G13+H13+I13)+J13,-2) | N13: 25600 | O13: ==+N13-K13
B14: 10 | C14: 1栋305 | D14: 88.78 | E14: 住宅 | F14: 26800 | G14: -0.0434 | H14: 0 | J14: 0 | K14: ==ROUND(+F14*(1+G14+H14+I14)+J14,-2) | N14: 25600 | O14: ==+N14-K14
B15: 11 | C15: 1栋306 | D15: 88.78 | E15: 住宅 | F15: 26800 | G15: -0.0434 | H15: 0 | J15: 0 | K15: ==ROUND(+F15*(1+G15+H15+I15)+J15,-2) | N15: 25600 | O15: ==+N15-K15
B16: 12 | C16: 1栋401 | D16: 88.9 | E16: 住宅 | F16: 26800 | G16: -0.0403 | H16: 0 | J16: 0 | K16: ==ROUND(+F16*(1+G16+H16+I16)+J16,-2) | N16: 25700 | O16: ==+N16-K16
B17: 13 | C17: 1栋402 | D17: 98.63 | E17: 住宅 | F17: 26800 | G17: -0.0403 | H17: 0 | J17: 0 | K17: ==ROUND(+F17*(1+G17+H17+I17)+J17,-2) | N17: 25700 | O17: ==+N17-K17
... B23: 19 | C23: 1栋502 | D23: 98.63 | E23: 住宅 | F23: 26800 | G23: -0.0372 | H23: 0 | J23: 0 | K23: ==ROUND(+F23*(1+G23+H23+I23)+J23,-2) | N23: 25800 | O23: ==+N23-K23
B24: 20 | C24: 1栋503 | D24: 98.63 | E24: 住宅 | H24: 0 | K24: 19920 | L24: 已售未签约，按合同价评估 | N24: 19920.247 | O24: ==+N24-K24
B25: 21 | C25: 1栋504 | D25: 78.98 | E25: 住宅 | F25: 26800 | G25: -0.0372 | H25: 0 | J25: 0 | K25: ==ROUND(+F25*(1+G25+H25+I25)+J25,-2) | N25: 25800 | O25: ==+N25-K25
B26: 22 | C26: 1栋505 | D26: 88.78 | E26: 住宅 | F26: 26800 | G26: -0.0372 | H26: 0 | J26: 0 | K26: ==ROUND(+F26*(1+G26+H26+I26)+J26,-2) | N26: 25800 | O26: ==+N26-K26
B27: 23 | C27: 1栋506 | D27: 88.78 | E27: 住宅 | F27: 26800 | G27: -0.0372 | H27: 0 | J27: 0 | K27: ==ROUND(+F27*(1+G27+H27+I27)+J27,-2) | N27: 25800 | O27: ==+N27-K27
B28: 24 | C28: 1栋601 | D28: 88.9 | E28: 住宅 | F28: 26800 | G28: -0.0341 | H28: 0 | J28: 0 | K28: ==ROUND(+F28*(1+G28+H28+I28)+J28,-2) | N28: 25900 | O28: ==+N28-K28
B29: 25 | C29: 1栋603 | D29: 98.63 | E29: 住宅 | F29: 26800 | G29: -0.0341 | H29: 0 | J29: 0 | K29: ==ROUND(+F29*(1+G29+H29+I29)+J29,-2) | N29: 25900 | O29: ==+N29-K29
B30: 26 | C30: 1栋604 | D30: 78.98 | E30: 住宅 | F30: 26800 | G30: -0.0341 | H30: 0 | J30: 0 | K30: ==ROUND(+F30*(1+G30+H30+I30)+J30,-2) | N30: 25900 | O30: ==+N30-K30
B31: 27 | C31: 1栋606 | D31: 88.78 | E31: 住宅 | F31: 26800 | G31: -0.0341 | H31: 0 | J31: 0 | K31: ==ROUND(+F31*(1+G31+H31+I31)+J31,-2) | N31: 25900 | O31: ==+N31-K31
B32: 28 | C32: 1栋701 | D32: 88.9 | E32: 住宅 | H32: 0 | K32: 25000 | L32: 已售未签约，按合同价评估 | N32: 25000 | O32: ==+N32-K32
B33: 29 | C33: 1栋704 | D33: 78.98 | E33: 住宅 | F33: 26800 | G33: -0.031 | H33: 0 | J33: 0 | K33: ==ROUND(+F33*(1+G33+H33+I33)+J33,-2) | N33: 26000 | O33: ==+N33-K33
B34: 30 | C34: 1栋705 | D34: 88.78 | E34: 住宅 | F34: 26800 | G34: -0.031 | H34: 0 | J34: 0 | K34: ==ROUND(+F34*(1+G34+H34+I34)+J34,-2) | N34: 26000 | O34: ==+N34-K34
B35: 31 | C35: 1栋706 | D35: 88.78 | E35: 住宅 | F35: 26800 | G35: -0.031 | H35: 0 | J35: 0 | K35: ==ROUND(+F35*(1+G35+H35+I35)+J35,-2) | N35: 26000 | O35: ==+N35-K35
B36: 32 | C36: 1栋802 | D36: 98.63 | E36: 住宅 | F36: 26800 | G36: -0.0279 | H36: 0 | J36: 0 | K36: ==ROUND(+F36*(1+G36+H36+I36)+J36,-2) | N36: 26100 | O36: ==+N36-K36
B37: 33 | C37: 1栋805 | D37: 88.78 | E37: 住宅 | F37: 26800 | G37: -0.0279 | H37: 0 | J37: 0 | K37: ==ROUND(+F37*(1+G37+H37+I37)+J37,-2) | N37: 26100 | O37: ==+N37-K37
B38: 34 | C38: 1栋806 | D38: 88.78 | E38: 住宅 | F38: 26800 | G38: -0.0279 | H38: 0 | J38: 0 | K38: ==ROUND(+F38*(1+G38+H38+I38)+J38,-2) | N38: 26100 | O38: ==+N38-K38
B39: 35 | C39: 1栋902 | D39: 98.63 | E39: 住宅 | F39: 26800 | G39: -0.0248 | H39: 0 | J39: 0 | K39: ==ROUND(+F39*(1+G39+H39+I39)+J39,-2) | N39: 26100 | O39: ==+N39-K39
B40: 36 | C40: 1栋906 | D40: 88.78 | E40: 住宅 | F40: 26800 | G40: -0.0248 | H40: 0 | J40: 0 | K40: ==ROUND(+F40*(1+G40+H40+I40)+J40,-2) | N40: 26100 | O40: ==+N40-K40
B41: 37 | C41: 1栋1006 | D41: 88.78 | E41: 住宅 | F41: 26800 | G41: -0.0217 | H41: 0 | J41: 0 | K41: ==ROUND(+F41*(1+G41+H41+I41)+J41,-2) | N41: 26200 | O41: ==+N41-K41
B42: 38 | C42: 1栋1102 | D42: 98.63 | E42: 住宅 | F42: 26800 | G42: -0.0186 | H42: 0 | J42: 0 | K42: ==ROUND(+F42*(1+G42+H42+I42)+J42,-2) | N42: 26300 | O42: ==+N42-K42
B43: 39 | C43: 1栋1103 | D43: 98.63 | E43: 住宅 | F43: 26800 | G43: -0.0186 | H43: 0 | J43: 0 | K43: ==ROUND(+F43*(1+G43+H43+I43)+J43,-2) | N43: 26300 | O43: ==+N43-K43
B44: 40 | C44: 1栋1106 | D44: 88.78 | E44: 住宅 | F44: 26800 | G44: -0.0186 | H44: 0 | J44: 0 | K44: ==ROUND(+F44*(1+G44+H44+I44)+J44,-2) | N44: 26300 | O44: ==+N44-K44
... B82: 78 | C82: 1栋3206 | D82: 88.78 | E82: 住宅 | F82: 26800 | G82: 0 | H82: 0 | J82: 0 | K82: ==ROUND(+F82*(1+G82+H82+I82)+J82,-2) | N82: 26800 | O82: ==+N82-K82
B83: 79 | C83: 2栋202 | D83: 117.92 | E83: 住宅 | H83: 0 | K83: 17228 | L83: 已售未签约，按合同价评估 | N83: 17228.087 | O83: ==+N83-K83
B84: 80 | C84: 2栋2704 | D84: 88.42 | E84: 住宅 | H84: 0 | K84: 17586 | L84: 已售未签约，按合同价评估 | N84: 17586.338 | O84: ==+N84-K84
...

Sheet 住宅-收益法测算
B2: 序号 | C2: 项目名称 | E2: 计算方法及说明 | G2: 计算结果 | I2: 个人出租房屋只交房产税和个人所得税
B3: 1 | C3: 租赁面积（m2） | E3: 产权证载建筑面积 | G3: ==评估明细表!M6
B4: 2 | C4: 第1年净收益（元/m2)（A） | E4: 年有效毛收入-年运营费用 | G4: ==G5-G11 | I4: 评估基准日 | J4: ==评估明细表!J2
B5: 2.1 | C5: 年有效毛收入（元/m2） | E5: 年潜在毛收入×（1-年空置率）×（1-年租金损失率） | G5: ==G6*(1-G9)*(1-G10) | I5: 土地使用权到期 | J5: ==+评估明细表!H6
B6: （1） | C6: 年潜在毛收入（元/m2） | E6: （潜在毛租金收入+其他收入）×12 | G6: ==ROUND((G7+G8)*12,2) | H6: 0.05 | I6: 土地剩余年限 | J6: ==ROUND((J5-J4)/365,2)
C7: 其中 | D7: 潜在毛租金收入（元/m2/月） | E7: 参考珠海市住房和城乡建设局公布的《2024年珠海市房屋租赁市场平均租金情况》，香洲区域的平均商品住宅租金价格为42.59元/平方米，评估对象室内为精装修，已达到可出租状态，故设定租金单价为42.59元/平方米。 | G7: 42.59 | I7: 建筑物结构 | J7: 钢混
D8: 其他收入（元/m2/月） | E8: 其他收入主要是押金产生的利息，押金一般为两个月租金，利息按同期一年期定期存款利率（1.5%）计 | G8: ==G7*2*(1.5%/12) | I8: 建筑物经济耐用年限 | J8: 60
B9: （2） | C9: 年空置率 | E9: 每年正常的空置1个月，即（1/12）×100 | G9: ==1/12*100% | I9: 建成时间 | J9: ==+评估明细表!K6
B10: （3） | C10: 年租金损失率 | E10: 出租房均有一定数额押金，且租金期初支付， 故基本不存在损失 | G10: 0 | I10: 已经使用年限 | J10: ==ROUND((J4-J9)/365,2)
B11: 2.2 | C11: 年运营费用 | E11: （1）~（8）合计 | G11: ==SUM(G12:G20) | I11: 建筑物剩余使用年限 | J11: ==J8-J10 | K11: ==J11/J8
B12: （1） | C12: 房产税 | E12: 年有效毛收入（不含税）的12% | F12: 0.12 | G12: ==(G5-H13)*F12
B13: （2） | C13: 增值税 | E13: 年有效毛收入÷（1+5%）×5% | F13: 0.05 | G13: ==+H13 | H13: ==G5/(1+H6)*H6
B14: （3） | C14: 城市维护建设税 | E14: 增值税的7% | F14: 0.07 | G14: ==H13*F14
B15: （4） | C15: 教育费附加 | E15: 增值税的3% | F15: 0.03 | G15: ==H13*F15
B16: （5） | C16: 地方教育费附加 | E16: 增值税的2% | F16: 0.02 | G16: ==H13*F16
B17: （6） | C17: 印花税 | E17: 对个人出租、承租住房签订的租赁合同，免征印花税 | F17: 0 | G17: ==G5*F17
B18: （7） | C18: 维修费 | E18: 维修费用由承租方支付 | F18: 0 | G18: ==ROUND(G5*F18,2)
B19: （8） | C19: 管理费 | E19: 由承租方承担，故不考虑管理费用 | F19: 0 | G19: ==G5*F19
B20: （9） | C20: 保险费 | E20: 不考虑保险费 | F20: 0 | G20: ==+J22*F20 | I20: 建筑重置单价 | J20: ==3187+1500
B21: 3 | C21: 收益期 | E21: ==IF(J6<J11,"本次测算以土地剩余使用年限为收益期","本次测算以建筑物剩余经济寿命为收益期") | G21: ==IF(J6<J11,J6,J11) | I21: 成新率
C22: 其中： | E22: 净收益递增年限（n1）为 | G22: ==IF(G21<40,G21,40) | I22: 重置现值 | J22: ==ROUND(+J20*J21,0)
E23: 固定收益年限（n2）为 | G23: ==G21-G22
B24: 4 | C24: 报酬率（Y） | E24: 无风险报酬率+风险报酬率 | G24: ==+'住宅-收益率'!O14
B25: 5 | C25: 净收益变化趋势 | D25: 收益年递增比率（g） | E25: 周边同类物业净收益变化趋势，确定净收益每年按比例递增。 | G25: 0.015
D26: 收益递增年限（n1） | E26: 收益自第二年开始递增，第N1年后租金固定至期末 | G26: ==G22
B27: 6 | C27: 收益单价值（元）（V） | E27: V={A/(Y-g)×[1-((1+g)/(1+Y))^n1 ]+[A(1+g)^(n1-1)]/Y/(1+Y)^n1 ×[1- 1/(1+Y)^n2 ]} | G27: ==ROUND((G4/(G24-G25)*(1-((1+G25)/(1+G24))^G26)+(G4*(1+G25)^(G26-1))/G24/(1+G24)^G26*(1-1/(1+G24)^G23)),-1) | H27: 收益法单价 | I27: ==1-I28 | J27: ==+G27
H28: 市场法单价 | I28: 1 | J28: ==+市场价比较法!T34
H29: 评估单价 | J29: ==ROUND(+J27*I27+J28*I28,-1)

Sheet 租金比较法
A1: 可比实例比较因素 | D1: 评估对象 | E1: 可比实例1 | F1: 可比实例2 | G1: 可比实例3 | I1: 可比实例 比较因素 | L1: ==D1 | M1: ==E1 | N1: ==F1 | O1: ==G1 | Q1: 可比实例 比较因素 | T1: ==E1 | W1: ==F1 | Z1: ==G1
D2: ==+市场价比较法!D2 | E2: 惠景慧园2栋5层住宅 | F2: 雅居乐国际花园6栋16层住宅 | G2: 万科翡翠中央2栋12层住宅 | L2: ==D2 | M2: ==E2 | N2: ==F2 | O2: ==G2 | T2: ==E2 | W2: ==F2 | Z2: ==G2
A4: 租金单价（元/㎡/月) | D4: 待估 | E4: 30 | F4: 28 | G4: 28 | I4: ==A4 | L4: ==D4 | M4: ==E4 | N4: ==F4 | O4: ==G4 | Q4: ==I4 | T4: ==M4 | W4: ==N4 | Z4: ==O4
A5: 交易情况 | D5: 正常 | E5: 正常 | F5: 正常 | G5: 正常 | I5: ==A5 | L5: 100 | M5: 100 | N5: 100 | O5: 100 | Q5: ==I5 | T5: ==L5 | U5: / | V5: ==M5 | W5: ==T5 | X5: / | Y5: ==N5 | Z5: ==T5 | AA5: / | AB5: ==O5
A6: 交易日期 | D6: 45291 | E6: 45242 | F6: 45262 | G6: 45279 | I6: ==A6 | L6: 100 | M6: 100 | N6: 100 | O6: 100 | Q6: ==I6 | T6: ==L6 | U6: / | V6: ==M6 | W6: ==T6 | X6: / | Y6: ==N6 | Z6: ==T6 | AA6: / | AB6: ==O6
A7: 一、区位状况 | B7: 地理位置 | C7: 与有关重要场所的距离 | D7: ==+市场价比较法!D7 | E7: 距城轨珠海北站约700米，距离北站宝龙城购物中心约600米，距大德世贸广场约400米 | F7: 距城轨珠海北站约1200米，距离北站宝龙城购物中心约1100米，距大德世贸广场约700米 | G7: 距离北站宝龙城购物中心约400米，距城轨珠海北站约700米，距大德世贸广场约400米 | I7: 一、区位状况 | J7: 地理位置 | K7: 坐落、方位与有关重要场所的距离 | L7: 100 | M7: 100 | N7: 100 | O7: 100 | Q7: 一、区位状况 | R7: 地理位置 | S7: 坐落、方位与有关重要场所的距离 | T7: ==L7 | U7: / | V7: ==M7 | W7: ==T7 | X7: / | Y7: ==N7 | Z7: ==T7 | AA7: / | AB7: ==O7
C8: 临街（路、巷）状况 | D8: 临近干道情侣中路 | E8: 临近干道情侣中路 | F8: 临近干道情侣中路 | G8: 临近干道情侣中路 | K8: 临街（路、巷）状况 | L8: 100 | M8: 100 | N8: 100 | O8: 100 | S8: 临街（路、巷）状况 | T8: ==L8 | U8: / | V8: ==M8 | W8: ==T8 | X8: / | Y8: ==N8 | Z8: ==T8 | AA8: / | AB8: ==O8
C9: 朝向 | D9: ==+市场价比较法!D9 | E9: 南向 | F9: 南向 | G9: 南向 | K9: 朝向 | L9: 100 | M9: 100 | N9: 100 | O9: 100 | S9: 朝向 | T9: ==L9 | U9: / | V9: ==M9 | W9: ==T9 | X9: / | Y9: ==N9 | Z9: ==T9 | AA9: / | AB9: ==O9
C10: 楼层 | D10: ==+市场价比较法!D10 | E10: 地上22层/位于第5层 | F10: 地上24层/位于第20层 | G10: 地上15层/位于第12层 | K10: 楼层 | L10: 100 | M10: 100 | N10: 100 | O10: 100 | S10: 楼层 | T10: ==L10 | U10: / | V10: ==M10 | W10: ==T10 | X10: / | Y10: ==N10 | Z10: ==T10 | AA10: / | AB10: ==O10
B11: 交通条件 | C11: 道路状况 | D11: ==+市场价比较法!D11 | E11: 临近金峰北路、创新八路、科技八路，道路通达度较好 | F11: 临近兴南路、兴中路、科创纵三路，道路通达度较好 | G11: 临近科创纵三路、金业南路，道路通达度好 | J11: 交通条件 | K11: 道路状况 | L11: 100 | M11: 100 | N11: 100 | O11: 100 | R11: 交通条件 | S11: 道路状况 | T11: ==L11 | U11: / | V11: ==M11 | W11: ==T11 | X11: / | Y11: ==N11 | Z11: ==T11 | AA11: / | AB11: ==O11
C12: 出入可用的公共交通工具及便利程度 | D12: ==+市场价比较法!D12 | E12: 距“惠景慧园”公交站约50米，有Z71路、3A、K1等多路公交线路，公共交通便利程度较好。 | F12: 距离“科创纵三路中”约400米，距“惠景慧园”公交站约800米，有Z71路、3A、K1等多路公交线路，公共交通便利程度一般。 | G12: 距离“科创纵三路中”约50米，距“城轨珠海北站”公交站约600米，有Z71路、3A、72A等多路公交线路，公共交通便利程度一般。 | K12: 出入可用的公共交通工具及便利程度 | L12: 100 | M12: 102 | N12: 100 | O12: 100 | S12: 出入可用的公共交通工具及便利程度 | T12: ==L12 | U12: / | V12: ==M12 | W12: ==T12 | X12: / | Y12: ==N12 | Z12: ==T12 | AA12: / | AB12: ==O12
C13: 停车便利程度 | D13: 设地下停车场，车位数量较多，停车便利程度较好 | E13: 设地下停车场，车位数量较多，停车便利程度较好 | F13: 设地下停车场，车位数量较多，停车便利程度较好 | G13: 设地下停车场，车位数量较多，停车便利程度较好 | K13: 停车便利程度 | L13: 100 | M13: 100 | N13: 100 | O13: 100 | S13: 停车便利程度 | T13: ==L13 | U13: / | V13: ==M13 | W13: ==T13 | X13: / | Y13: ==N13 | Z13: ==T13 | AA13: / | AB13: ==O13
C14: 交通管理情况 | D14: 无特别交通管制 | E14: 无特别交通管制 | F14: 无特别交通管制 | G14: 无特别交通管制 | K14: 交通管理情况 | L14: 100 | M14: 100 | N14: 100 | O14: 100 | S14: 交通管理情况 | T14: ==L14 | U14: / | V14: ==M14 | W14: ==T14 | X14: / | Y14: ==N14 | Z14: ==T14 | AA14: / | AB14: ==O14
B15: 外部配套设施状况 | C15: 基础设施 | D15: 已达到“五通”一平，基础设施完善 | E15: 已达到“五通”一平，基础设施完善 | F15: 已达到“五通”一平，基础设施完善 | G15: 已达到“五通”一平，基础设施完善 | J15: 外部配套设施状况 | K15: 基础设施 | L15: 100 | M15: 100 | N15: 100 | O15: 100 | R15: 外部配套设施状况 | S15: 基础设施 | T15: ==L15 | U15: / | V15: ==M15 | W15: ==T15 | X15: / | Y15: ==N15 | Z15: ==T15 | AA15: / | AB15: ==O15
C16: 公共服务设施 | D16: ==+市场价比较法!D16 | E16: ==+市场价比较法!E16 | F16: 有超市、酒店、银行、XX中学、XX小学、XX幼儿园等，公共服务设施较完善。 | G16: 有超市、酒店、银行、XX中学、XX小学、XX幼儿园等，公共服务设施较完善。 | K16: 公共服务设施 | L16: 100 | M16: 100 | N16: 100 | O16: 100 | S16: 公共服务设施 | T16: ==L16 | U16: / | V16: ==M16 | W16: ==T16 | X16: / | Y16: ==N16 | Z16: ==T16 | AA16: / | AB16: ==O16
B17: 周围环境状况 | D17: 自然环境、人文环境良好，绿化景观良好。 | E17: 自然环境、人文环境良好，绿化景观良好。 | F17: 自然环境、人文环境良好，绿化景观良好。 | G17: 自然环境、人文环境良好，绿化景观良好。 | J17: 周围环境状况 | L17: 100 | M17: 100 | N17: 100 | O17: 100 | R17: 周围环境状况 | T17: ==L17 | U17: / | V17: ==M17 | W17: ==T17 | X17: / | Y17: ==N17 | Z17: ==T17 | AA17: / | AB17: ==O17
A18: 二、权益状况 | B18: 租赁用途 | D18: 住宅 | E18: 住宅 | F18: 住宅 | G18: 住宅 | I18: ==A18 | J18: 租赁用途 | L18: 100 | M18: 100 | N18: 100 | O18: 100 | Q18: ==I18 | R18: 租赁用途 | T18: ==L18 | U18: / | V18: ==M18 | W18: ==T18 | X18: / | Y18: ==N18 | Z18: ==T18 | AA18: / | AB18: ==O18
B19: 租赁期限 | D19: 1 | E19: 1 | F19: 1 | G19: 1 | J19: 租赁期限 | L19: 100 | M19: 100 | N19: 100 | O19: 100 | R19: 租赁期限 | T19: ==L19 | U19: / | V19: ==M19 | W19: ==T19 | X19: / | Y19: ==N19 | Z19: ==T19 | AA19: / | AB19: ==O19
B20: 维修费、物业管理费等负担情况 | D20: 租金含租赁税费由出租人承担，其余一切费用均由承租人承担。 | E20: 租金含租赁税费由出租人承担，其余一切费用均由承租人承担。 | F20: 租金含租赁税费由出租人承担，其余一切费用均由承租人承担。 | G20: 租金含租赁税费由出租人承担，其余一切费用均由承租人承担。 | J20: 维修费、物业管理费等负担情况 | L20: 100 | M20: 100 | N20: 100 | O20: 100 | R20: 维修费、物业管理费等负担情况 | T20: ==L20 | U20: / | V20: ==M20 | W20: ==T20 | X20: / | Y20: ==N20 | Z20: ==T20 | AA20: / | AB20: ==O20
B21: 承租人对租赁标的享有权益的限制情况 | D21: 无限制 | E21: 无限制 | F21: 无限制 | G21: 无限制 | J21: 承租人对租赁标的享有权益的限制情况 | L21: 100 | M21: 100 | N21: 100 | O21: 100 | R21: 承租人对租赁标的享有权益的限制情况 | T21: ==L21 | U21: / | V21: ==M21 | W21: ==T21 | X21: / | Y21: ==N21 | Z21: ==T21 | AA21: / | AB21: ==O21
B22: 物业管理状况 | D22: 物业管理较好 | E22: 物业管理较好 | F22: 物业管理较好 | G22: 物业管理较好 | J22: 物业管理状况 | L22: 100 | M22: 100 | N22: 100 | O22: 100 | R22: 物业管理状况 | T22: ==L22 | U22: / | V22: ==M22 | W22: ==T22 | X22: / | Y22: ==N22 | Z22: ==T22 | AA22: / | AB22: ==O22
A23: 三、实物状况 | B23: 建筑规模（㎡） | D23: ==+市场价比较法!D24 | E23: 81.39 | F23: 100 | G23: 109 | I23: ==A23 | J23: 建筑规模 | L23: 100 | M23: 100 | N23: 100 | O23: 100 | Q23: ==I23 | R23: 建筑规模 | T23: ==L23 | U23: / | V23: ==M23 | W23: ==T23 | X23: / | Y23: ==N23 | Z23: ==T23 | AA23: / | AB23: ==O23
B24: 建筑外观 | D24: 外观档次较高档 | E24: 外观档次较高档 | F24: 外观档次较高档 | G24: 外观档次较高档 | J24: 建筑外观 | L24: 100 | M24: 100 | N24: 100 | O24: 100 | R24: 建筑外观 | T24: ==L24 | U24: / | V24: ==M24 | W24: ==T24 | X24: / | Y24: ==N24 | Z24: ==T24 | AA24: / | AB24: ==O24
B25: 建筑结构 | D25: 钢混结构 | E25: 钢混结构 | F25: 钢混结构 | G25: 钢混结构 | J25: 建筑结构 | L25: 100 | M25: 100 | N25: 100 | O25: 100 | R25: 建筑结构 | T25: ==L25 | U25: / | V25: ==M25 | W25: ==T25 | X25: / | Y25: ==N25 | Z25: ==T25 | AA25: / | AB25: ==O25
B26: 设施设备 | D26: 2部电梯，水、电、消防设施齐备，未配备家具。 | E26: 2部电梯，水、电、消防设施齐备，家具齐备。 | F26: 3部电梯，水、电、消防设施齐备，家具齐备。 | G26: 2部电梯，水、电、消防设施齐备，家具齐备。 | J26: 设施设备 | L26: 100 | M26: 102 | N26: 102 | O26: 102 | R26: 设施设备 | T26: ==L26 | U26: / | V26: ==M26 | W26: ==T26 | X26: / | Y26: ==N26 | Z26: ==T26 | AA26: / | AB26: ==O26
B27: 装饰装修 | D27: 精装修 | E27: 精装修 | F27: 精装修 | G27: 精装修 | J27: 装饰装修 | L27: 100 | M27: 100 | N27: 100 | O27: 100 | R27: 装饰装修 | T27: ==L27 | U27: / | V27: ==M27 | W27: ==T27 | X27: / | Y27: ==N27 | Z27: ==T27 | AA27: / | AB27: ==O27
B28: 建筑性能 | D28: 建筑性能较好 | E28: 建筑性能较好 | F28: 建筑性能较好 | G28: 建筑性能较好 | J28: 建筑性能 | L28: 100 | M28: 100 | N28: 100 | O28: 100 | R28: 建筑性能 | T28: ==L28 | U28: / | V28: ==M28 | W28: ==T28 | X28: / | Y28: ==N28 | Z28: ==T28 | AA28: / | AB28: ==O28
B29: 空间布局 | D29: 空间布局合理 | E29: 空间布局合理 | F29: 空间布局合理 | G29: 空间布局合理 | J29: 空间布局 | L29: 100 | M29: 100 | N29: 100 | O29: 100 | R29: 空间布局 | T29: ==L29 | U29: / | V29: ==M29 | W29: ==T29 | X29: / | Y29: ==N29 | Z29: ==T29 | AA29: / | AB29: ==O29
B30: 新旧程度 | D30: ==+市场价比较法!D31 | E30: 2018年 | F30: 2021年 | G30: 2021年 | J30: 新旧程度 | L30: 100 | M30: 100 | N30: 100 | O30: 100 | R30: 新旧程度 | T30: ==L30 | U30: / | V30: ==M30 | W30: ==T30 | X30: / | Y30: ==N30 | Z30: ==T30 | AA30: / | AB30: ==O30
Q31: 比较单价（元/㎡/月) | T31: ==T4*T5/V5*T6/V6*100/(V7+V8+V9+V10+V11+V12+V13+V14+V15+V16+V17-1000)*100/(V18+V19+V20+V21+V22-400)*100/(V23+V24+V25+V26+V27+V28+V29+V30-700) | W31: ==W4*W5/Y5*W6/Y6*100/(Y7+Y8+Y9+Y10+Y11+Y12+Y13+Y14+Y15+Y16+Y17-1000)*100/(Y18+Y19+Y20+Y21+Y22-400)*100/(Y23+Y24+Y25+Y26+Y27+Y28+Y29+Y30-700) | Z31: ==Z4*Z5/AB5*Z6/AB6*100/(AB7+AB8+AB9+AB10+AB11+AB12+AB13+AB14+AB15+AB16+AB17-1000)*100/(AB18+AB19+AB20+AB21+AB22-400)*100/(AB23+AB24+AB25+AB26+AB27+AB28+AB29+AB30-700)
Q32: 权重 | T32: 1∕3 | W32: 1∕3 | Z32: 1∕3
Q33: 评估单价（元/㎡/月） | T33: ==ROUND((T31+W31+Z31)/3,0)
T35: ==(T4-T31)/T4 | W35: ==(W4-W31)/W4 | Z35: ==(Z4-Z31)/Z4
O39: ==8500/125.14
O56: ==8800/141.26

Sheet 租金单价
P6: ==2500/89.07
P18: ==2600/103.73
L32: ==2500/81.39
P115: ==2800/100
O145: ==3100/109

Sheet 住宅-收益率
B2: 名称 | C2: 取值范围 | E2: 影响因素 | F2: 所占 比例 | G2: 分值
G3: 高 | H3: 中高 | I3: 中 | J3: 中低 | K3: 低 | L3: （取值）
B4: 投资风险 补偿率 | C4: 0 | D4: ==L4/10*F4 | E4: 投资周期风险 | F4: 0.1 | G4: 9-10 | H4: 7-8 | I4: 5-6 | J4: 3-4 | K4: 1-2 | L4: 3
D5: ==L5/10*F5 | E5: 退出损失风险 | F5: 0.2 | G5: 9-10 | H5: 7-8 | I5: 5-6 | J5: 3-4 | K5: 1-2 | L5: 3 | N5: 五年期国债收益率 | O5: 1.5379
D6: ==L6/10*F6 | E6: 竞争能力风险 | F6: 0.15 | G6: 9-10 | H6: 7-8 | I6: 5-6 | J6: 3-4 | K6: 1-2 | L6: 3
D7: ==L7/10*F7 | E7: 投资规模风险 | F7: 0.1 | G7: 9-10 | H7: 7-8 | I7: 5-6 | J7: 3-4 | K7: 1-2 | L7: 3
D8: ==L8/10*F8 | E8: 收益稳定性风险 | F8: 0.1 | G8: 9-10 | H8: 7-8 | I8: 5-6 | J8: 3-4 | K8: 1-2 | L8: 3
D9: ==L9/10*F9 | E9: 市场规模和成熟程度风险 | F9: 0.15 | G9: 9-10 | H9: 7-8 | I9: 5-6 | J9: 3-4 | K9: 1-2 | L9: 3 | N9: 一年期定期存款基准利率 | O9: 0.015
D10: ==L10/10*F10 | E10: 市场失衡的可能性风险 | F10: 0.1 | G10: 9-10 | H10: 7-8 | I10: 5-6 | J10: 3-4 | K10: 1-2 | L10: 3 | N10: ==B4 | O10: ==C12
C11: 0.04 | D11: ==L11/10*F11 | E11: 政策风险 | F11: 0.1 | G11: 9-10 | H11: 7-8 | I11: 5-6 | J11: 3-4 | K11: 1-2 | L11: 3 | N11: 缺乏流动性补偿率 | O11: 0.01
B12: 合计 | C12: ==D12*(C11-C4) | D12: ==SUM(D4:D11) | E12: - | F12: ==SUM(F4:F11) | G12: - | H12: - | I12: - | J12: - | K12: - | L12: - | N12: 投资带来的优惠率 | O12: 0.005
N13: ==B19 | O13: ==C23
O14: ==ROUND(O9+O10+O13+O11-O12,4)
B17: 名称 | C17: 取值范围 | E17: 影响因素 | F17: 所占 比例 | G17: 分值
G18: 高 | H18: 中高 | I18: 中 | J18: 中低 | K18: 低 | L18: （取值）
B19: 管理负担 补偿 | C19: 0 | D19: ==L19/10*F19 | E19: 管理难易程度 | F19: 0.25 | G19: 9-10 | H19: 7-8 | I19: 5-6 | J19: 3-4 | K19: 1-2 | L19: 2
D20: ==L20/10*F20 | E20: 管理对价值的影响程度 | F20: 0.25 | G20: 9-10 | H20: 7-8 | I20: 5-6 | J20: 3-4 | K20: 1-2 | L20: 2
D21: ==L21/10*F21 | E21: 管理的成本费用水平 | F21: 0.25 | G21: 9-10 | H21: 7-8 | I21: 5-6 | J21: 3-4 | K21: 1-2 | L21: 2
C22: 0.03 | D22: ==L22/10*F22 | E22: 专业性 | F22: 0.25 | G22: 9-10 | H22: 7-8 | I22: 5-6 | J22: 3-4 | K22: 1-2 | L22: 2
B23: 合计 | C23: ==D23*(C22-C19) | D23: ==SUM(D19:D22) | E23: - | F23: ==SUM(F19:F22) | G23: - | H23: - | I23: - | J23: - | K23: - | L23: -
B25: 基准地价修正：商业用地土地还原率6.15%，办公还原率6.04%，住宅还原率5.95%，工业5原还率5.38%，公服一土地还原率5.42%，公服二土地还原率4.54%

Sheet 市场价比较法
A1: 可比实例比较因素 | D1: 评估对象 | E1: 可比实例1 | F1: 可比实例2 | G1: 可比实例3 | I1: 可比实例 比较因素 | L1: ==D1 | M1: ==E1 | N1: ==F1 | O1: ==G1 | Q1: 可比实例 比较因素 | T1: ==E1 | W1: ==F1 | Z1: ==G1
D2: ==+评估明细表!D6 | E2: XX苑住宅 | F2: XX湾山庄住宅 | G2: XX市XX路XX山庄XX栋别墅 | L2: ==D2 | M2: ==E2 | N2: ==F2 | O2: ==G2 | T2: ==E2 | W2: ==F2 | Z2: ==G2
A4: 成交价格（元/㎡) | D4: 待估 | E4: 31000 | F4: 30000 | G4: 28000 | I4: ==A4 | L4: ==D4 | M4: ==E4 | N4: ==F4 | O4: ==G4 | Q4: ==I4 | T4: ==M4 | W4: ==N4 | Z4: ==O4
A5: 交易情况 | D5: 正常 | E5: 正常 | F5: 正常 | G5: 法拍 | I5: ==A5 | L5: 100 | M5: 100 | N5: 100 | O5: 85 | Q5: ==I5 | T5: ==L5 | U5: / | V5: ==M5 | W5: ==T5 | X5: / | Y5: ==N5 | Z5: ==T5 | AA5: / | AB5: ==O5
A6: 交易日期 | D6: ==评估明细表!J2 | E6: 42821 | F6: 42861 | G6: 42689 | I6: ==A6 | L6: 100 | M6: 100 | N6: 100 | O6: 100 | Q6: ==I6 | T6: ==L6 | U6: / | V6: ==M6 | W6: ==T6 | X6: / | Y6: ==N6 | Z6: ==T6 | AA6: / | AB6: ==O6
A7: 区位状况 | B7: 地理位置 | C7: 与有关重要场所的距离 | D7: 距香洲区政府约11公里，位置较好。 | E7: 距香洲区政府约11公里，位置较好。 | F7: 距香洲区政府约12.3公里，位置较好。 | G7: 距香洲区政府约22公里，位置较好。 | I7: ==A7 | J7: 地理位置 | K7: 坐落、方位与有关重要场所的距离 | L7: 100 | M7: 100 | N7: 100 | O7: 100 | Q7: ==A7 | R7: 地理位置 | S7: 坐落、方位与有关重要场所的距离 | T7: ==L7 | U7: / | V7: ==M7 | W7: ==T7 | X7: / | Y7: ==N7 | Z7: ==T7 | AA7: / | AB7: ==O7
C8: 临街（路、巷）状况 | D8: 临近干道XX大道 | E8: 临近干道XX大道 | F8: 临近干道XX大道 | G8: 临近干道XX大道 | K8: 临街（路、巷）状况 | L8: 100 | M8: 100 | N8: 100 | O8: 100 | S8: 临街（路、巷）状况 | T8: ==L8 | U8: / | V8: ==M8 | W8: ==T8 | X8: / | Y8: ==N8 | Z8: ==T8 | AA8: / | AB8: ==O8
C9: 朝向 | D9: 南北向 | E9: 南北向 | F9: 南北向 | G9: 南北向 | K9: 朝向 | L9: 100 | M9: 100 | N9: 100 | O9: 100 | S9: 朝向 | T9: ==L9 | U9: / | V9: ==M9 | W9: ==T9 | X9: / | Y9: ==N9 | Z9: ==T9 | AA9: / | AB9: ==O9 | AG9: 3
C10: 楼层 | D10: 共5层/位于第1-5层 | E10: 共3层/位于第1-3层 | F10: 共2层/位于第1-2层 | G10: 共2层/位于第1-2层 | K10: 楼层 | L10: 100 | M10: 100 | N10: 100 | O10: 100 | S10: 楼层 | T10: ==L10 | U10: / | V10: ==M10 | W10: ==T10 | X10: / | Y10: ==N10 | Z10: ==T10 | AA10: / | AB10: ==O10 | AD10: 32 | AE10: 38 | AF10: 38 | AG10: 39
B11: 交通条件 | C11: 道路状况 | D11: 临近干道XX大道，道路通达度较好 | E11: 临近干道XX大道，道路通达度较好 | F11: 临近干道XX大道，道路通达度较好 | G11: 临近干道XX大道，道路通达度较好 | J11: 交通条件 | K11: 道路状况 | L11: 100 | M11: 100 | N11: 100 | O11: 100 | R11: 交通条件 | S11: 道路状况 | T11: ==L11 | U11: / | V11: ==M11 | W11: ==T11 | X11: / | Y11: ==N11 | Z11: ==T11 | AA11: / | AB11: ==O11 | AD11: ==+AD10/$AG$9 | AE11: ==+AE10/$AG$9 | AF11: ==+AF10/$AG$9 | AG11: ==+AG10/$AG$9
C12: 出入可用的公共交通工具及便利程度 | D12: 距离“XX站”公交站约500米，附近有K1路、10A路、69路、3A路、3路等多数公交线路，公共交通便利度较好 | E12: 距离“XX站”公交站约300米，附近有K1路、10A路、69路、3A路、3路等多数公交线路，公共交通便利度较好 | F12: 距离“XX站”公交站约300米，附近有K1路、10A路、69路、3A路、3路等多数公交线路，公共交通便利度较好 | G12: 距离“XX站”公交站约500米，附近有K1路、10A路、69路、3A路、3路等多数公交线路，公共交通便利度较好 | K12: 出入可用的公共交通工具及便利程度 | L12: 100 | M12: 100 | N12: 100 | O12: 100 | S12: 出入可用的公共交通工具及便利程度 | T12: ==L12 | U12: / | V12: ==M12 | W12: ==T12 | X12: / | Y12: ==N12 | Z12: ==T12 | AA12: / | AB12: ==O12 | AD12: ==+D10 | AE12: ==+E10 | AF12: ==+F10 | AG12: ==+G10
C13: 停车便利程度 | D13: 设地上及地下停车场，车位数量较多，停车便利程度较好 | E13: 设地上及地下停车场，车位数量较多，停车便利程度较好 | F13: 设地上及地下停车场，车位数量较多，停车便利程度较好 | G13: 设地上停车场，车位数量较多，停车便利程度较好 | K13: 停车便利程度 | L13: 100 | M13: 100 | N13: 100 | O13: 100 | S13: 停车便利程度 | T13: ==L13 | U13: / | V13: ==M13 | W13: ==T13 | X13: / | Y13: ==N13 | Z13: ==T13 | AA13: / | AB13: ==O13 | AD13: 位于低区 | AE13: 位于低区 | AF13: 位于中区 | AG13: 位于中区
C14: 交通管理情况 | D14: 无特别交通管制 | E14: 无特别交通管制 | F14: 无特别交通管制 | G14: 无特别交通管制 | K14: 交通管理情况 | L14: 100 | M14: 100 | N14: 100 | O14: 100 | S14: 交通管理情况 | T14: ==L14 | U14: / | V14: ==M14 | W14: ==T14 | X14: / | Y14: ==N14 | Z14: ==T14 | AA14: / | AB14: ==O14
B15: 外部配套设施状况 | C15: 基础设施 | D15: 已达到“五通”一平，基础设施完善 | E15: 已达到“五通”一平，基础设施完善 | F15: 已达到“五通”一平，基础设施完善 | G15: 已达到“五通”一平，基础设施完善 | J15: 外部配套设施状况 | K15: 基础设施 | L15: 100 | M15: 100 | N15: 100 | O15: 100 | R15: 外部配套设施状况 | S15: 基础设施 | T15: ==L15 | U15: / | V15: ==M15 | W15: ==T15 | X15: / | Y15: ==N15 | Z15: ==T15 | AA15: / | AB15: ==O15
C16: 公共服务设施 | D16: 周围公共、生活配套设施齐全，附近有XX幼儿园、XX小学及幼儿园、XX超市、XX森林公园等，生活便利度较好。 | E16: 周围公共、生活配套设施齐全，附近有XX幼儿园、XX小学及幼儿园、XX超市、XX森林公园等，生活便利度较好。 | F16: 周围公共、生活配套设施齐全，附近有XX幼儿园、XX小学及幼儿园、XX超市、XX森林公园等，生活便利度较好。 | G16: 周围公共、生活配套设施齐全，附近有XX幼儿园、XX中学、XX医院、XX超市、XX赛车场、XX俱乐部等，生活便利度较好。 | K16: 公共服务设施 | L16: 100 | M16: 100 | N16: 100 | O16: 100 | S16: 公共服务设施 | T16: ==L16 | U16: / | V16: ==M16 | W16: ==T16 | X16: / | Y16: ==N16 | Z16: ==T16 | AA16: / | AB16: ==O16
B17: 周围环境状况 | C17: 环境质量 | D17: 自然环境、人文环境良好。 | E17: 自然环境、人文环境良好。 | F17: 自然环境、人文环境良好。 | G17: 自然环境、人文环境良好。 | J17: 周围环境状况 | K17: ==C17 | L17: 100 | M17: 100 | N17: 100 | O17: 100 | R17: 周围环境状况 | S17: ==C17 | T17: ==L17 | U17: / | V17: ==M17 | W17: ==T17 | X17: / | Y17: ==N17 | Z17: ==T17 | AA17: / | AB17: ==O17
C18: 景观 | D18: 小区园景 | E18: 小区园景 | F18: 小区园景 | G18: 小区园景 | K18: ==C18 | L18: 100 | M18: 100 | N18: 100 | O18: 100 | S18: ==C18 | T18: ==L18 | U18: / | V18: ==M18 | W18: ==T18 | X18: / | Y18: ==N18 | Z18: ==T18 | AA18: / | AB18: ==O18
A19: 权益状况 | B19: 权益状况 | C19: 规划用途 | D19: 住宅 | E19: 住宅 | F19: 住宅 | G19: 住宅 | I19: ==A19 | J19: ==+C19 | L19: 100 | M19: 100 | N19: 100 | O19: 100 | Q19: ==I19 | R19: ==+J19 | T19: ==L19 | U19: / | V19: ==M19 | W19: ==T19 | X19: / | Y19: ==N19 | Z19: ==T19 | AA19: / | AB19: ==O19
J20: ==+C20 | L20: 100 | M20: 100 | N20: 100 | O20: 100 | R20: ==+J20 | T20: ==L20 | U20: / | V20: ==M20 | W20: ==T20 | X20: / | Y20: ==N20 | Z20: ==T20 | AA20: / | AB20: ==O20
C21: 容积率 | J21: ==+C21 | L21: 100 | M21: 100 | N21: 100 | O21: 100 | R21: ==+J21 | T21: ==L21 | U21: / | V21: ==M21 | W21: ==T21 | X21: / | Y21: ==N21 | Z21: ==T21 | AA21: / | AB21: ==O21
C22: 租约限制 | D22: 无限制 | E22: 无限制 | F22: 无限制 | G22: 无限制 | J22: ==+C22 | L22: 100 | M22: 100 | N22: 100 | O22: 100 | R22: ==+J22 | T22: ==L22 | U22: / | V22: ==M22 | W22: ==T22 | X22: / | Y22: ==N22 | Z22: ==T22 | AA22: / | AB22: ==O22
C23: 物业管理状况 | D23: 物业管理良好 | E23: 物业管理良好 | F23: 物业管理良好 | G23: 物业管理良好 | J23: ==+C23 | L23: 100 | M23: 100 | N23: 100 | O23: 100 | R23: ==+J23 | T23: ==L23 | U23: / | V23: ==M23 | W23: ==T23 | X23: / | Y23: ==N23 | Z23: ==T23 | AA23: / | AB23: ==O23
A24: 实物状况 | B24: 实物状况 | C24: 建筑规模（㎡） | D24: ==评估明细表!M8 | E24: 450 | F24: 200 | G24: 270 | I24: ==A24 | J24: 建筑规模 | L24: 100 | M24: 100 | N24: 100 | O24: 100 | Q24: ==I24 | R24: 建筑规模 | T24: ==L24 | U24: / | V24: ==M24 | W24: ==T24 | X24: / | Y24: ==N24 | Z24: ==T24 | AA24: / | AB24: ==O24
C25: 建筑外观 | D25: 外观档次较高档 | E25: 外观档次较高档 | F25: 外观档次较高档 | G25: 外观档次一般 | J25: ==+C25 | L25: 100 | M25: 100 | N25: 100 | O25: 95 | R25: ==+C25 | T25: ==L25 | U25: / | V25: ==M25 | W25: ==T25 | X25: / | Y25: ==N25 | Z25: ==T25 | AA25: / | AB25: ==O25
C26: 建筑结构 | D26: 钢混结构 | E26: 钢混结构 | F26: 钢混结构 | G26: 钢混结构 | J26: ==+C26 | L26: 100 | M26: 100 | N26: 100 | O26: 100 | R26: ==+C26 | T26: ==L26 | U26: / | V26: ==M26 | W26: ==T26 | X26: / | Y26: ==N26 | Z26: ==T26 | AA26: / | AB26: ==O26
C27: 设施设备 | D27: 1部电梯，水、电、消防设施齐备 | E27: 未设电梯，水、电、消防设施齐备 | F27: 未设电梯，水、电、消防设施齐备 | G27: 未设电梯，水、电、消防设施齐备 | J27: ==+C27 | L27: 100 | M27: 95 | N27: 95 | O27: 95 | R27: ==+C27 | T27: ==L27 | U27: / | V27: ==M27 | W27: ==T27 | X27: / | Y27: ==N27 | Z27: ==T27 | AA27: / | AB27: ==O27
C28: 装饰装修 | D28: 精装 | E28: 毛坯 | F28: 毛坯 | G28: 简装 | J28: ==+C28 | L28: 100 | M28: 90 | N28: 90 | O28: 93 | R28: ==+C28 | T28: ==L28 | U28: / | V28: ==M28 | W28: ==T28 | X28: / | Y28: ==N28 | Z28: ==T28 | AA28: / | AB28: ==O28
C29: 建筑性能 | D29: 建筑性能较好 | E29: 建筑性能较好 | F29: 建筑性能较好 | G29: 建筑性能较好 | J29: ==+C29 | L29: 100 | M29: 100 | N29: 100 | O29: 100 | R29: ==+C29 | T29: ==L29 | U29: / | V29: ==M29 | W29: ==T29 | X29: / | Y29: ==N29 | Z29: ==T29 | AA29: / | AB29: ==O29
C30: 空间布局 | D30: 双拼别墅，空间布局合理 | E30: 联排别墅，空间布局合理 | F30: 双拼别墅，空间布局合理 | G30: 独栋别墅，空间布局合理 | J30: ==+C30 | L30: 100 | M30: 95 | N30: 100 | O30: 115 | R30: ==+C30 | T30: ==L30 | U30: / | V30: ==M30 | W30: ==T30 | X30: / | Y30: ==N30 | Z30: ==T30 | AA30: / | AB30: ==O30
C31: 新旧程度 | D31: 建成于2011年7月 | E31: 建成于2016年 | F31: 建成于2002年 | G31: 建成于1998年 | J31: ==+C31 | L31: 100 | M31: 103 | N31: 93 | O31: 89 | R31: ==+C31 | T31: ==L31 | U31: / | V31: ==M31 | W31: ==T31 | X31: / | Y31: ==N31 | Z31: ==T31 | AA31: / | AB31: ==O31
Q32: 比较单价（元/㎡) | T32: ==ROUND(T4*T5/V5*T6/V6*100/(V7+V8+V9+V10+V11+V12+V13+V14+V15+V16+V17+V18-1100)*100/(V19+V20+V21+V22+V23-400)*100/(V24+V25+V26+V27+V28+V29+V30+V31-700),0) | W32: ==ROUND(W4*W5/Y5*W6/Y6*100/(Y7+Y8+Y9+Y10+Y11+Y12+Y13+Y14+Y15+Y16+Y17+Y18-1100)*100/(Y19+Y20+Y21+Y22+Y23-400)*100/(Y24+Y25+Y26+Y27+Y28+Y29+Y30+Y31-700),0) | Z32: ==ROUND(Z4*Z5/AB5*Z6/AB6*100/(AB7+AB8+AB9+AB10+AB11+AB12+AB13+AB14+AB15+AB16+AB17+AB18-1100)*100/(AB19+AB20+AB21+AB22+AB23-400)*100/(AB24+AB25+AB26+AB27+AB28+AB29+AB30+AB31-700),0)
Q33: 权重 | T33: 0.5 | W33: 0.3 | Z33: 0.2 | AD33: ==+MIN(T32:AB32)/MAX(T32:AB32)-1
E34: ==$D$24-E24 | F34: ==$D$24-F24 | G34: ==$D$24-G24 | Q34: 评估单价（元/㎡） | T34: ==ROUND((T32*T33+W32*W33+Z32*Z33),-1)
T36: ==(T4-T32)/T4 | W36: ==(W4-W32)/W4 | Z36: ==(Z4-Z32)/Z4

Sheet 二手房案例
S11: 24912 | T11: 0.97 | U11: ==ROUND(S11*T11,0)
S12: 25623 | T12: 0.91 | U12: ==ROUND(S12*T12,0)
S13: 26761 | T13: 0.88 | U13: ==ROUND(S13*T13,0)
A29: XX市XX路XX山庄XX栋别墅 - 司法拍卖 - 阿里资产 (taobao.com)

Sheet 可比案例
G52: XX居
G53: 1100000 | H53: 49 | I53: ==+G53/H53
G54: 1100000 | H54: 49 | I54: ==+G54/H54
G55: 1600000 | H55: 69 | I55: ==+G55/H55
G56: 1600000 | H56: 69 | I56: ==+G56/H56
G58: 2300000 | H58: 95 | I58: ==+G58/H58
G59: 2300000 | H59: 95 | I59: ==+G59/H59

Sheet 租金案例
